Workbook

Sheet Dirty Data
A1: CaseID | B1: District | C1: Sex | D1: Age
A2: D0093 | B2: Highland | C2: M | D2: 24
A3: D0080 | B3: Northgate | C3: female | D3: 46
A4: D0112 | B4: Northgate | C4: female | D4: 70
A5: D0111 | B5: Highland | C5: F
A6: D0116 | B6: Northgate | C6: Male | D6: 32
A7: D0050 | B7: Highland | C7: M | D7: 87
A8: D0124 | B8: Northgate | C8: female | D8: 19
A9: D0142 | B9: Eastfield | C9: M | D9: 71
A10: D0059 | B10: Eastfield | C10: female | D10: 83
A11: D0088 | B11: Eastfield | C11: Femle | D11: 24
A12: D0092 | B12: Central | C12: Male | D12: 999
A13: D0004 | B13: Central | C13: female | D13: 27
A14: D0075 | B14: Highland | C14: Female | D14: 61
A15: D0123 | B15: Eastfield | C15: Female | D15: 64
A16: D0054 | B16: Central | C16: Female | D16: 75
A17: D0077 | B17: Central | C17: F | D17: 43
... A24: D0009 | B24: Central | C24: male | D24: 80
A25: D0042 | B25: Northgate | C25: female
A26: D0037 | B26: Central | C26: Male | D26: 93
A27: D0106 | B27: Highland | C27: Female | D27: 51
A28: D0062 | B28: Highland | C28: Female | D28: 13
A29: D0113 | B29: Northgate | C29: Male | D29: 1
A30: D0073 | B30: Riverside | C30: Female | D30: 15
A31: D0078 | B31: Riverside | C31: Female | D31: 88
A32: D0048 | B32: Riverside | C32: male | D32: 55
A33: D0083 | B33: Riverside | C33: F | D33: 11
A34: D0125 | B34: Eastfield | C34: female
A35: D0006 | B35: Highland | C35: Male | D35: 30
A36: D0095 | B36: Riverside | C36: M | D36: 10
A37: D0046 | B37: Highland | C37: Male | D37: 21
A38: D0086 | B38: Eastfield | C38: female | D38: 64
A39: D0053 | B39: Northgate | C39: F | D39: 29
A40: D0131 | B40: Eastfield | C40: female | D40: 71
A41: D0090 | B41: Northgate | C41: male | D41: 66
A42: D0020 | B42: Eastfield | C42: male | D42: 63
A43: D0055 | B43: Northgate | C43: M | D43: 36
A44: D0126 | B44: Highland | C44: Femle | D44: 23
A45: D0140 | B45: Highland | C45: female | D45: 68
A46: D0036 | B46: Riverside | C46: Female
...

Sheet Cleaning Formulas
A1: Data Cleaning — Worked Formulas (reference to 'Dirty Data' sheet)
A3: ='Dirty Data'!A2 -> D0093 | B3: =TRIM(PROPER('Dirty Data'!B2)) -> Highland | C3: =_xlfn.IFS(OR('Dirty Data'!C2="M",'Dirty Data'!C2="m",'Dirty Data'!C2="Male",'Dirty Data'!C2="male"),"Male",OR('Dirty Data'!C2="F",'Dirty Data'!C2="f",'Dirty Data'!C2="Female",'Dirty Data'!C2="female",'Dirty Data'!C2="Femle"),"Female",TRUE(),"Unrecognized") -> Male | D3: ='Dirty Data'!D2 -> 24 | E3: =_xlfn.IFS(D3="","Missing",D3<0,"Invalid",D3>120,"Invalid",TRUE(),"Valid") -> Valid | F3: =IF(COUNTIFS('Dirty Data'!$B$2:$B$166,'Dirty Data'!B2,'Dirty Data'!$C$2:$C$166,'Dirty Data'!C2,'Dirty Data'!$D$2:$D$166,'Dirty Data'!D2)>1,"Possible Duplicate","Unique") -> Unique
A4: ='Dirty Data'!A3 -> D0080 | B4: =TRIM(PROPER('Dirty Data'!B3)) -> Northgate | C4: =_xlfn.IFS(OR('Dirty Data'!C3="M",'Dirty Data'!C3="m",'Dirty Data'!C3="Male",'Dirty Data'!C3="male"),"Male",OR('Dirty Data'!C3="F",'Dirty Data'!C3="f",'Dirty Data'!C3="Female",'Dirty Data'!C3="female",'Dirty Data'!C3="Femle"),"Female",TRUE(),"Unrecognized") -> Female | D4: ='Dirty Data'!D3 -> 46 | E4: =_xlfn.IFS(D4="","Missing",D4<0,"Invalid",D4>120,"Invalid",TRUE(),"Valid") -> Valid | F4: =IF(COUNTIFS('Dirty Data'!$B$2:$B$166,'Dirty Data'!B3,'Dirty Data'!$C$2:$C$166,'Dirty Data'!C3,'Dirty Data'!$D$2:$D$166,'Dirty Data'!D3)>1,"Possible Duplicate","Unique") -> Unique
A5: ='Dirty Data'!A4 -> D0112 | B5: =TRIM(PROPER('Dirty Data'!B4)) -> Northgate | C5: =_xlfn.IFS(OR('Dirty Data'!C4="M",'Dirty Data'!C4="m",'Dirty Data'!C4="Male",'Dirty Data'!C4="male"),"Male",OR('Dirty Data'!C4="F",'Dirty Data'!C4="f",'Dirty Data'!C4="Female",'Dirty Data'!C4="female",'Dirty Data'!C4="Femle"),"Female",TRUE(),"Unrecognized") -> Female | D5: ='Dirty Data'!D4 -> 70 | E5: =_xlfn.IFS(D5="","Missing",D5<0,"Invalid",D5>120,"Invalid",TRUE(),"Valid") -> Valid | F5: =IF(COUNTIFS('Dirty Data'!$B$2:$B$166,'Dirty Data'!B4,'Dirty Data'!$C$2:$C$166,'Dirty Data'!C4,'Dirty Data'!$D$2:$D$166,'Dirty Data'!D4)>1,"Possible Duplicate","Unique") -> Unique
A6: ='Dirty Data'!A5 -> D0111 | B6: =TRIM(PROPER('Dirty Data'!B5)) -> Highland | C6: =_xlfn.IFS(OR('Dirty Data'!C5="M",'Dirty Data'!C5="m",'Dirty Data'!C5="Male",'Dirty Data'!C5="male"),"Male",OR('Dirty Data'!C5="F",'Dirty Data'!C5="f",'Dirty Data'!C5="Female",'Dirty Data'!C5="female",'Dirty Data'!C5="Femle"),"Female",TRUE(),"Unrecognized") -> Female | D6: ='Dirty Data'!D5 -> 0 | E6: =_xlfn.IFS(D6="","Missing",D6<0,"Invalid",D6>120,"Invalid",TRUE(),"Valid") -> Missing | F6: =IF(COUNTIFS('Dirty Data'!$B$2:$B$166,'Dirty Data'!B5,'Dirty Data'!$C$2:$C$166,'Dirty Data'!C5,'Dirty Data'!$D$2:$D$166,'Dirty Data'!D5)>1,"Possible Duplicate","Unique") -> Unique
A7: ='Dirty Data'!A6 -> D0116 | B7: =TRIM(PROPER('Dirty Data'!B6)) -> Northgate | C7: =_xlfn.IFS(OR('Dirty Data'!C6="M",'Dirty Data'!C6="m",'Dirty Data'!C6="Male",'Dirty Data'!C6="male"),"Male",OR('Dirty Data'!C6="F",'Dirty Data'!C6="f",'Dirty Data'!C6="Female",'Dirty Data'!C6="female",'Dirty Data'!C6="Femle"),"Female",TRUE(),"Unrecognized") -> Male | D7: ='Dirty Data'!D6 -> 32 | E7: =_xlfn.IFS(D7="","Missing",D7<0,"Invalid",D7>120,"Invalid",TRUE(),"Valid") -> Valid | F7: =IF(COUNTIFS('Dirty Data'!$B$2:$B$166,'Dirty Data'!B6,'Dirty Data'!$C$2:$C$166,'Dirty Data'!C6,'Dirty Data'!$D$2:$D$166,'Dirty Data'!D6)>1,"Possible Duplicate","Unique") -> Unique
A8: ='Dirty Data'!A7 -> D0050 | B8: =TRIM(PROPER('Dirty Data'!B7)) -> Highland | C8: =_xlfn.IFS(OR('Dirty Data'!C7="M",'Dirty Data'!C7="m",'Dirty Data'!C7="Male",'Dirty Data'!C7="male"),"Male",OR('Dirty Data'!C7="F",'Dirty Data'!C7="f",'Dirty Data'!C7="Female",'Dirty Data'!C7="female",'Dirty Data'!C7="Femle"),"Female",TRUE(),"Unrecognized") -> Male | D8: ='Dirty Data'!D7 -> 87 | E8: =_xlfn.IFS(D8="","Missing",D8<0,"Invalid",D8>120,"Invalid",TRUE(),"Valid") -> Valid | F8: =IF(COUNTIFS('Dirty Data'!$B$2:$B$166,'Dirty Data'!B7,'Dirty Data'!$C$2:$C$166,'Dirty Data'!C7,'Dirty Data'!$D$2:$D$166,'Dirty Data'!D7)>1,"Possible Duplicate","Unique") -> Unique
A9: ='Dirty Data'!A8 -> D0124 | B9: =TRIM(PROPER('Dirty Data'!B8)) -> Northgate | C9: =_xlfn.IFS(OR('Dirty Data'!C8="M",'Dirty Data'!C8="m",'Dirty Data'!C8="Male",'Dirty Data'!C8="male"),"Male",OR('Dirty Data'!C8="F",'Dirty Data'!C8="f",'Dirty Data'!C8="Female",'Dirty Data'!C8="female",'Dirty Data'!C8="Femle"),"Female",TRUE(),"Unrecognized") -> Female | D9: ='Dirty Data'!D8 -> 19 | E9: =_xlfn.IFS(D9="","Missing",D9<0,"Invalid",D9>120,"Invalid",TRUE(),"Valid") -> Valid | F9: =IF(COUNTIFS('Dirty Data'!$B$2:$B$166,'Dirty Data'!B8,'Dirty Data'!$C$2:$C$166,'Dirty Data'!C8,'Dirty Data'!$D$2:$D$166,'Dirty Data'!D8)>1,"Possible Duplicate","Unique") -> Unique
A10: ='Dirty Data'!A9 -> D0142 | B10: =TRIM(PROPER('Dirty Data'!B9)) -> Eastfield | C10: =_xlfn.IFS(OR('Dirty Data'!C9="M",'Dirty Data'!C9="m",'Dirty Data'!C9="Male",'Dirty Data'!C9="male"),"Male",OR('Dirty Data'!C9="F",'Dirty Data'!C9="f",'Dirty Data'!C9="Female",'Dirty Data'!C9="female",'Dirty Data'!C9="Femle"),"Female",TRUE(),"Unrecognized") -> Male | D10: ='Dirty Data'!D9 -> 71 | E10: =_xlfn.IFS(D10="","Missing",D10<0,"Invalid",D10>120,"Invalid",TRUE(),"Valid") -> Valid | F10: =IF(COUNTIFS('Dirty Data'!$B$2:$B$166,'Dirty Data'!B9,'Dirty Data'!$C$2:$C$166,'Dirty Data'!C9,'Dirty Data'!$D$2:$D$166,'Dirty Data'!D9)>1,"Possible Duplicate","Unique") -> Possible Duplicate
A11: ='Dirty Data'!A10 -> D0059 | B11: =TRIM(PROPER('Dirty Data'!B10)) -> Eastfield | C11: =_xlfn.IFS(OR('Dirty Data'!C10="M",'Dirty Data'!C10="m",'Dirty Data'!C10="Male",'Dirty Data'!C10="male"),"Male",OR('Dirty Data'!C10="F",'Dirty Data'!C10="f",'Dirty Data'!C10="Female",'Dirty Data'!C10="female",'Dirty Data'!C10="Femle"),"Female",TRUE(),"Unrecognized") -> Female | D11: ='Dirty Data'!D10 -> 83 | E11: =_xlfn.IFS(D11="","Missing",D11<0,"Invalid",D11>120,"Invalid",TRUE(),"Valid") -> Valid | F11: =IF(COUNTIFS('Dirty Data'!$B$2:$B$166,'Dirty Data'!B10,'Dirty Data'!$C$2:$C$166,'Dirty Data'!C10,'Dirty Data'!$D$2:$D$166,'Dirty Data'!D10)>1,"Possible Duplicate","Unique") -> Possible Duplicate
A12: ='Dirty Data'!A11 -> D0088 | B12: =TRIM(PROPER('Dirty Data'!B11)) -> Eastfield | C12: =_xlfn.IFS(OR('Dirty Data'!C11="M",'Dirty Data'!C11="m",'Dirty Data'!C11="Male",'Dirty Data'!C11="male"),"Male",OR('Dirty Data'!C11="F",'Dirty Data'!C11="f",'Dirty Data'!C11="Female",'Dirty Data'!C11="female",'Dirty Data'!C11="Femle"),"Female",TRUE(),"Unrecognized") -> Female | D12: ='Dirty Data'!D11 -> 24 | E12: =_xlfn.IFS(D12="","Missing",D12<0,"Invalid",D12>120,"Invalid",TRUE(),"Valid") -> Valid | F12: =IF(COUNTIFS('Dirty Data'!$B$2:$B$166,'Dirty Data'!B11,'Dirty Data'!$C$2:$C$166,'Dirty Data'!C11,'Dirty Data'!$D$2:$D$166,'Dirty Data'!D11)>1,"Possible Duplicate","Unique") -> Unique
A13: ='Dirty Data'!A12 -> D0092 | B13: =TRIM(PROPER('Dirty Data'!B12)) -> Central | C13: =_xlfn.IFS(OR('Dirty Data'!C12="M",'Dirty Data'!C12="m",'Dirty Data'!C12="Male",'Dirty Data'!C12="male"),"Male",OR('Dirty Data'!C12="F",'Dirty Data'!C12="f",'Dirty Data'!C12="Female",'Dirty Data'!C12="female",'Dirty Data'!C12="Femle"),"Female",TRUE(),"Unrecognized") -> Male | D13: ='Dirty Data'!D12 -> 999 | E13: =_xlfn.IFS(D13="","Missing",D13<0,"Invalid",D13>120,"Invalid",TRUE(),"Valid") -> Invalid | F13: =IF(COUNTIFS('Dirty Data'!$B$2:$B$166,'Dirty Data'!B12,'Dirty Data'!$C$2:$C$166,'Dirty Data'!C12,'Dirty Data'!$D$2:$D$166,'Dirty Data'!D12)>1,"Possible Duplicate","Unique") -> Unique
A14: ='Dirty Data'!A13 -> D0004 | B14: =TRIM(PROPER('Dirty Data'!B13)) -> Central | C14: =_xlfn.IFS(OR('Dirty Data'!C13="M",'Dirty Data'!C13="m",'Dirty Data'!C13="Male",'Dirty Data'!C13="male"),"Male",OR('Dirty Data'!C13="F",'Dirty Data'!C13="f",'Dirty Data'!C13="Female",'Dirty Data'!C13="female",'Dirty Data'!C13="Femle"),"Female",TRUE(),"Unrecognized") -> Female | D14: ='Dirty Data'!D13 -> 27 | E14: =_xlfn.IFS(D14="","Missing",D14<0,"Invalid",D14>120,"Invalid",TRUE(),"Valid") -> Valid | F14: =IF(COUNTIFS('Dirty Data'!$B$2:$B$166,'Dirty Data'!B13,'Dirty Data'!$C$2:$C$166,'Dirty Data'!C13,'Dirty Data'!$D$2:$D$166,'Dirty Data'!D13)>1,"Possible Duplicate","Unique") -> Unique
... A167: ='Dirty Data'!A166 -> D0022 | B167: =TRIM(PROPER('Dirty Data'!B166)) -> Highland | C167: =_xlfn.IFS(OR('Dirty Data'!C166="M",'Dirty Data'!C166="m",'Dirty Data'!C166="Male",'Dirty Data'!C166="male"),"Male",OR('Dirty Data'!C166="F",'Dirty Data'!C166="f",'Dirty Data'!C166="Female",'Dirty Data'!C166="female",'Dirty Data'!C166="Femle"),"Female",TRUE(),"Unrecognized") -> Female | D167: ='Dirty Data'!D166 -> 58 | E167: =_xlfn.IFS(D167="","Missing",D167<0,"Invalid",D167>120,"Invalid",TRUE(),"Valid") -> Valid | F167: =IF(COUNTIFS('Dirty Data'!$B$2:$B$166,'Dirty Data'!B166,'Dirty Data'!$C$2:$C$166,'Dirty Data'!C166,'Dirty Data'!$D$2:$D$166,'Dirty Data'!D166)>1,"Possible Duplicate","Unique") -> Unique
A169: Summary Counts
A170: Missing ages | B170: =COUNTIF(E4:E167,"Missing") -> 14
A171: Invalid ages | B171: =COUNTIF(E4:E167,"Invalid") -> 3
A172: Possible duplicate rows | B172: =COUNTIF(F4:F167,"Possible Duplicate") -> 38
A173: Unrecognized sex entries | B173: =COUNTIF(C4:C167,"Unrecognized") -> 0

Sheet Instructions
A1: Data Cleaning Practice Workbook — Instructions
A3: Purpose: practice cleaning data in Excel (Monday session: 'Cleaning data in Excel').
A5: 'Dirty Data' contains deliberately messy records: inconsistent Sex spellings ('M','m','Male','male','Femle'), blank ages, three implausible ages, and 15 duplicated rows mixed in among the data.
A6: 'Cleaning Formulas' shows the worked solution using TRIM, PROPER, IFS, and COUNTIFS, fully live — edit 'Dirty Data' and this sheet recalculates.
A8: Exercise steps:
A9: 1. Open 'Dirty Data' and scan the Sex column for spelling variants.
A10: 2. In 'Cleaning Formulas', study the Sex_clean formula (an IFS statement) and the Age_flag formula (flags Missing vs Invalid vs Valid without deleting anything).
A11: 3. Review the Duplicate_flag column and manually inspect a few flagged rows in 'Dirty Data' to confirm they are true duplicates.
A12: 4. Check the Summary Counts at the bottom of 'Cleaning Formulas' against your own manual count as a sanity check.
A13: 5. Apply Data Validation (Data tab > Data Validation > List) to the Sex column in a copy of 'Dirty Data' so future entries are restricted to 'Male' or 'Female'.
A15: Note: IFS() requires Excel 2019 or Microsoft 365 (or a current version of LibreOffice Calc). If your Excel version does not recognize IFS, use nested IF statements as a substitute.
